Workbook

Sheet Quantity Sheet
A1: Developer | B1: Name | C1: Number | D1: Bed no. | E1: Type | F1: Kitchen | G1: Robe | H1: Utility | I1: Vanity Unit | J1: Pantry
A2: MOCKDEV | B2: The Avenue MOCKSITE | C2: 1 | D2: 3 | E2: T3 | F2: 1 | G2: 3 | H2: 1 | I2: 1 | J2: 1
A3: MOCKDEV | B3: The Avenue MOCKSITE | C3: 2 | D3: 3 | E3: T3 | F3: 1 | G3: 3 | H3: 1 | I3: 1 | J3: 1
A4: MOCKDEV | B4: The Avenue MOCKSITE | C4: 3 | D4: 3 | E4: T3 | F4: 1 | G4: 3 | H4: 1 | I4: 1 | J4: 1
A5: MOCKDEV | B5: The Avenue MOCKSITE | C5: 4 | D5: 3 | E5: T3 | F5: 1 | G5: 3 | H5: 1 | I5: 1 | J5: 1
A6: MOCKDEV | B6: The Avenue MOCKSITE | C6: 5 | D6: 3 | E6: T3 | F6: 1 | G6: 3 | H6: 1 | I6: 1 | J6: 1
A7: MOCKDEV | B7: The Avenue MOCKSITE | C7: 6 | D7: 3 | E7: T3 | F7: 1 | G7: 3 | H7: 1 | I7: 1 | J7: 1
A8: MOCKDEV | B8: The Avenue MOCKSITE | C8: 7 | D8: 2 | E8: T2 | F8: 1 | G8: 2 | H8: 1 | I8: 0 | J8: 0
A9: MOCKDEV | B9: The Avenue MOCKSITE | C9: 8 | D9: 2 | E9: T2 | F9: 1 | G9: 2 | H9: 1 | I9: 0 | J9: 0
A10: MOCKDEV | B10: The Avenue MOCKSITE | C10: 9 | D10: 2 | E10: T2 | F10: 1 | G10: 2 | H10: 1 | I10: 0 | J10: 0
A11: MOCKDEV | B11: The Avenue MOCKSITE | C11: 10 | D11: 2 | E11: T2 | F11: 1 | G11: 2 | H11: 1 | I11: 0 | J11: 0
A12: MOCKDEV | B12: The Avenue MOCKSITE | C12: 11 | D12: 2 | E12: T2 | F12: 1 | G12: 2 | H12: 1 | I12: 0 | J12: 0
A13: MOCKDEV | B13: The Avenue MOCKSITE | C13: 12 | D13: 2 | E13: T2 | F13: 1 | G13: 2 | H13: 1 | I13: 0 | J13: 0
... A41: MOCKDEV | B41: The Lane MOCKSITE | C41: 16 | D41: 1 | E41: T1V | F41: 1 | G41: 1 | H41: 0 | I41: 0 | J41: 0

Sheet Spec Sheet
A1: Spec Type | B1: T1 | C1: T1V | D1: T2 | E1: T3
A2: To Supply
A3: Wall Unit Door | B3: Foil Wrap Door Light Grey Grain | C3: Light Grey U708 | D3: Foil Wrap Door Light Grey Grain | E3: Foil Wrap Door Light Grey Grain
A4: Wall Unit Carcass | B4: Bardolino Oak H1146 | C4: Bardolino Oak H1146 | D4: Bardolino Oak H1146 | E4: Bardolino Oak H1146
A5: Tall Unit Door | B5: Foil Wrap Door Light Grey Grain | C5: Light Grey U708 | D5: Foil Wrap Door Light Grey Grain | E5: Foil Wrap Door Light Grey Grain
A6: Tall Unit Carcass | B6: Bardolino Oak H1147 | C6: Bardolino Oak H1147 | D6: Bardolino Oak H1147 | E6: Bardolino Oak H1147
A7: Base Unit Door | B7: Foil Wrap Door Light Grey Grain | C7: Light Grey U708 | D7: Foil Wrap Door Light Grey Grain | E7: Foil Wrap Door Light Grey Grain
A8: Base Unit Carcass | B8: Bardolino Oak H1148 | C8: Bardolino Oak H1148 | D8: Bardolino Oak H1148 | E8: Bardolino Oak H1148
A9: Island Unit Door | B9: N/A | C9: N/A | D9: N/A | E9: Indigo Blue
A10: Island Unit Carcass | B10: N/A | C10: N/A | D10: N/A | E10: Bardolino Oak H1146
A11: Gables | B11: Light Grey Grain | C11: Light Grey U708 | D11: Light Grey Grain | E11: Light Grey Grain
A12: Tap & Sink
A13: Tap | B13: Hafele Swan Neck Veronese | C13: Hafele Swan Neck Veronese | D13: Hafele Swan Neck Veronese | E13: Hafele Swan Neck Veronese
A14: Sink | B14: Top Mounted Single Bowl | C14: Top Mounted Single Bowl | D14: Top Mounted Single Bowl | E14: Top Mounted Single Bowl
A15: Flow Restrictor | B15: N/A | C15: N/A | D15: N/A | E15: N/A
A16: Appliances
A17: Canope fan | B17: Hanso | C17: Hanso | D17: Hanso | E17: Hanso
A18: Hob | B18: N/A | C18: N/A | D18: Indesit - Built in - Ceramic Hob - RI860C | E18: Bosch - Ceramic Hob 60cm 4 - PKE61RAA8B
A19: Oven | B19: N/A | C19: N/A | D19: Indesit - Single Oven - IO233XUK | E19: Bosch - Built-in Single Oven - HHF113BA0B
A20: Microwave | B20: N/A | C20: N/A | D20: Daewoo - Freestanding - Microwave E30MXP03 | E20: Bosch - Built in Microwave - BFL523MB0B
A21: Fridge/freezer | B21: N/A | C21: N/A | D21: Indesit - Built in Fridge Freezer - INC18DO11B1 | E21: Bosch - Integrated - Fridge freezer - KIV87NSE0G
A22: Dishwasher | B22: N/A | C22: N/A | D22: Indesit - Built in Dishwasher - DIO3T131FE UK | E22: Bosch - Integrated - Dishwasher - SMV2HTX02G
A23: Washing Machine | B23: N/A | C23: N/A | D23: Indesit - Washing Machine - IM964MYTIME | E23: Bosch - Built in Washing Machine - WIW28502GB
A24: Dryer | B24: N/A | C24: N/A | D24: Indesit - Tumble Cond Dryer - FS I2 D81WUK | E24: Bosch - Tumble Dryer - WTH85225IE
A25: Accessories
A26: Bins | B26: Eltippi | C26: Eltippi | D26: Eltippi | E26: Eltippi
A27: Cutlery | B27: Grey Insert | C27: Grey Insert | D27: Grey Insert | E27: Grey Insert
A28: Vents | B28: Stainless Steel | C28: Stainless Steel | D28: Stainless Steel | E28: Stainless Steel
A29: Kitchen Handles | B29: Brushed Nickel H50 | C29: T-Bar | D29: Brushed Nickel H51 | E29: Brushed Nickel H51
A30: Robes Handles | B30: T-Bar | C30: T-Bar | D30: T-Bar | E30: T-Bar
A31: Robes
A32: Robe Carcass | B32: Light Grey U708 | C32: Light Grey U708 | D32: Light Grey U708 | E32: Light Grey U708
A33: Robe Door | B33: Light Grey U708 | C33: Light Grey U708 | D33: Light Grey U708 | E33: Light Grey U708
A34: Robe Gables | B34: Light Grey U708 | C34: Light Grey U708 | D34: Light Grey U708 | E34: Light Grey U708
A35: Utility
A36: Utility Unit | B36: N/A | C36: N/A | D36: N/A | E36: N/A
A37: Utility Gable | B37: Light Grey U708 | C37: N/A | D37: Light Grey U710 | E37: Light Grey U711
A38: Worktops & Splashbacks
A39: Kitchen Worktop | B39: 20mm Ice Crystal | C39: Levanto Marble | D39: 20mm Ice Crystal | E39: 20mm Ice Crystal
A40: Kitchen Backsplash | B40: 600mm Ice Crystal | C40: N/A | D40: 600mm Ice Crystal | E40: 600mm Ice Crystal
...

Sheet T1 Manifest
A1: Item Number | B1: Description | C1: Width | D1: Height | E1: Depth | F1: Item Description | G1: Room | H1: Qty
A2: 0 | B2: Brushed Nickel Handle H50 | C2: 160 | D2: 20 | E2: 30 | F2: Kitchen Handle - Brushed Nickel H50 | G2: Kitchen Accessories | H2: 10
A3: 1 | B3: B60 | C3: 870 | D3: 600 | E3: 570 | F3: 600mm Highline Base Unit | G3: Kitchen | H3: 2
A4: 2 | B4: B55 | C4: 870 | D4: 550 | E4: 570 | F4: 550mm Highline Base Unit | G4: Kitchen | H4: 1
A5: 3 | B5: BS60 | C5: 870 | D5: 600 | E5: 570 | F5: 600mm Sink Unit | G5: Kitchen | H5: 1
A6: 4 | B6: W60 | C6: 720 | D6: 600 | E6: 350 | F6: 600mm Medium Height Wall Unit | G6: Kitchen | H6: 2
A7: 5 | B7: WFAN60 | C7: 720 | D7: 600 | E7: 350 | F7: 600mm Medium Height Fan Unit | G7: Kitchen | H7: 1
A8: 6 | B8: Tall Gable | C8: 2350 | D8: 18 | E8: 600 | F8: Tall Gable | G8: Kitchen | H8: 1
A9: 7 | B9: Back Panel | C9: 890 | D9: 18 | E9: 1200 | F9: Back Panel | G9: Kitchen | H9: 1
A10: 8 | B10: Plinth X2 | C10: 2200 | D10: 18 | E10: 145 | F10: Plinth X2 | G10: Kitchen | H10: 2
A11: 9 | B11: Pelmet | C11: 2200 | D11: 18 | E11: 60 | F11: Pelmet | G11: Kitchen | H11: 1
A12: 10 | B12: Filler (100mm) | C12: 2200 | D12: 18 | E12: 100 | F12: Filler (100mm) | G12: Kitchen | H12: 1
A13: 11 | B13: Base Gable | C13: 890 | D13: 18 | E13: 600 | F13: Base Gable | G13: Utility | H13: 1
... A20: 26 | B20: Levanto Utility Worktop | C20: 25 | D20: 1200 | E20: 600 | F20: Levanto Marble Utility Worktop | G20: Utility | H20: 1

Sheet T1V Manifest
A1: Item Number | B1: Description | C1: Width | D1: Height | E1: Depth | F1: Item Description | G1: Room | H1: Qty
A2: 0 | B2: T-Bar Handle | C2: 160 | D2: 20 | E2: 30 | F2: Kitchen Handle - T-Bar | G2: Kitchen Accessories | H2: 8
A3: 1 | B3: B60 | C3: 870 | D3: 600 | E3: 570 | F3: 600mm Highline Base Unit | G3: Kitchen | H3: 2
A4: 2 | B4: BS60 | C4: 870 | D4: 600 | E4: 570 | F4: 600mm Sink Unit | G4: Kitchen | H4: 1
A5: 3 | B5: W60 | C5: 720 | D5: 600 | E5: 350 | F5: 600mm Medium Height Wall Unit | G5: Kitchen | H5: 2
A6: 4 | B6: WFAN60 | C6: 720 | D6: 600 | E6: 350 | F6: 600mm Medium Height Fan Unit | G6: Kitchen | H6: 1
A7: 5 | B7: Tall Gable | C7: 2350 | D7: 18 | E7: 600 | F7: Tall Gable | G7: Kitchen | H7: 1
A8: 6 | B8: Back Panel | C8: 890 | D8: 18 | E8: 1100 | F8: Back Panel | G8: Kitchen | H8: 1
A9: 7 | B9: Plinth X2 | C9: 2100 | D9: 18 | E9: 145 | F9: Plinth X2 | G9: Kitchen | H9: 2
A10: 8 | B10: Pelmet | C10: 2100 | D10: 18 | E10: 60 | F10: Pelmet | G10: Kitchen | H10: 1
A11: 9 | B11: Filler (100mm) | C11: 2100 | D11: 18 | E11: 100 | F11: Filler (100mm) | G11: Kitchen | H11: 1
A12: 20 | B12: Hanso | C12: 200 | D12: 500 | E12: 250 | F12: Hanso Canopy Fan | G12: Kitchen Accessories | H12: 1
A13: 21 | B13: TM Single Bowl Single Drainer | C13: 200 | D13: 550 | E13: 500 | F13: TM Single Bowl Single Drainer | G13: Kitchen Accessories | H13: 1
... A16: 24 | B16: Levanto Worktop | C16: 25 | D16: 2200 | E16: 600 | F16: Levanto Marble Kitchen Worktop | G16: Kitchen Accessories | H16: 1

Sheet T2 Manifest
A1: Item Number | B1: Description | C1: Width | D1: Height | E1: Depth | F1: Item Description | G1: Room | H1: Qty
A2: 0 | B2: Brushed Nickel Handle H51 | C2: 160 | D2: 20 | E2: 30 | F2: Kitchen Handle - Brushed Nickel H51 | G2: Kitchen Accessories | H2: 14
A3: 1 | B3: TFFINT | C3: 2300 | D3: 600 | E3: 570 | F3: Tall Fridge Freezer Unit | G3: Kitchen | H3: 1
A4: 2 | B4: B60 | C4: 870 | D4: 600 | E4: 570 | F4: 600mm Highline Base Unit | G4: Kitchen | H4: 2
A5: 3 | B5: PDDL90HOB | C5: 870 | D5: 900 | E5: 570 | F5: 900mm D/Line Pot Drawer Hob | G5: Kitchen | H5: 1
A6: 4 | B6: B55 | C6: 870 | D6: 550 | E6: 570 | F6: 550mm Highline Base Unit | G6: Kitchen | H6: 1
A7: 5 | B7: BS60 | C7: 870 | D7: 600 | E7: 570 | F7: 600mm Sink Unit | G7: Kitchen | H7: 1
A8: 6 | B8: W60 | C8: 720 | D8: 600 | E8: 350 | F8: 600mm Medium Height Wall Unit | G8: Kitchen | H8: 2
A9: 7 | B9: WFAN90 | C9: 720 | D9: 900 | E9: 350 | F9: 900mm Medium Height Fan Unit | G9: Kitchen | H9: 1
A10: 8 | B10: Tall Gable | C10: 2450 | D10: 18 | E10: 600 | F10: Tall Gable | G10: Kitchen | H10: 2
A11: 9 | B11: D/W Door | C11: 715 | D11: 595 | E11: 570 | F11: Dishwasher Door | G11: Kitchen | H11: 1
A12: 10 | B12: D/W Strap 600mm | C12: 600 | D12: 18 | E12: 500 | F12: Dishwasher Strap 600mm | G12: Kitchen | H12: 1
A13: 11 | B13: Back Panel | C13: 890 | D13: 18 | E13: 1500 | F13: Back Panel | G13: Kitchen | H13: 1
... A31: 43 | B31: Levanto Utility Worktop | C31: 25 | D31: 1400 | E31: 600 | F31: Levanto Marble Utility Worktop | G31: Utility | H31: 1

Sheet T3 Manifest
A1: Item Number | B1: Description | C1: Width | D1: Height | E1: Depth | F1: Item Description | G1: Room | H1: Qty
A2: 0 | B2: 32mm Chrome Knob | C2: 30 | D2: 30 | F2: Handles | G2: Kitchen | H2: 15
A3: 1 | B3: TFFINT | C3: 2300 | D3: 600 | E3: 570 | F3: Tall Fridge Freezer Unit | G3: Kitchen | H3: 1
A4: 2 | B4: B60 | C4: 870 | D4: 600 | E4: 570 | F4: 600mm Highline Base Unit | G4: Kitchen | H4: 1
A5: 3 | B5: PDDL90HOB | C5: 870 | D5: 900 | E5: 570 | F5: 900mm D/Line Pot Drawer Hob | G5: Kitchen | H5: 1
A6: 4 | B6: B60 | C6: 870 | D6: 600 | E6: 570 | F6: 600mm Highline Base Unit | G6: Kitchen | H6: 1
A7: 5 | B7: TSOM 460 Micro(Glenveagh 3) | C7: 2300 | D7: 600 | E7: 570 | F7: TSOM 460 Micro(Glenveagh 3) | G7: Kitchen | H7: 1
A8: 6 | B8: B55 | C8: 870 | D8: 550 | E8: 570 | F8: 550mm Highline Base Unit | G8: Kitchen | H8: 1
A9: 7 | B9: BS60 | C9: 870 | D9: 600 | E9: 570 | F9: 600mm Sink Unit | G9: Kitchen | H9: 1
A10: 8 | B10: W60 | C10: 720 | D10: 600 | E10: 350 | F10: 600mm Medium Height Wall Unit | G10: Kitchen | H10: 1
A11: 9 | B11: WFAN90 (New) | C11: 720 | D11: 900 | E11: 350 | F11: 900mm Medium Height Fan Unit | G11: Kitchen | H11: 1
A12: 10 | B12: W60 | C12: 720 | D12: 600 | E12: 350 | F12: 600mm Medium Height Wall Unit | G12: Kitchen | H12: 1
A13: 11 | B13: Tall Gable | C13: 2550 | D13: 18 | E13: 600 | F13: Tall Gable | G13: Kitchen | H13: 1
A14: 12 | B14: Tall Gable | C14: 2550 | D14: 18 | E14: 600 | F14: Tall Gable | G14: Kitchen | H14: 1
... A43: 46 | B43: Grey Cutlery Insert | C43: 500 | D43: 50 | E43: 450 | F43: Grey Cutlery Insert | G43: Kitchen Accessories | H43: 1

Sheet T1 Robe Manifest
A1: Item Number | B1: Description | C1: Width | D1: Height | E1: Depth | F1: Item Description | G1: Room | H1: Qty
A2: 0 | B2: Robe Side Panel | C2: 2100 | D2: 18 | E2: 600 | F2: Light Grey U708 Robe Side Panel | G2: Robe | H2: 2
A3: 1 | B3: Robe Top Panel | C3: 800 | D3: 18 | E3: 600 | F3: Light Grey U708 Robe Top Panel | G3: Robe | H3: 1
A4: 2 | B4: Robe Base Panel | C4: 800 | D4: 18 | E4: 600 | F4: Light Grey U708 Robe Base Panel | G4: Robe | H4: 1
A5: 3 | B5: Robe Shelf | C5: 760 | D5: 18 | E5: 550 | F5: Light Grey U708 Robe Shelf | G5: Robe | H5: 3
A6: 4 | B6: Robe Door | C6: 2100 | D6: 400 | E6: 18 | F6: Light Grey U708 Robe Door | G6: Robe | H6: 2
A7: 5 | B7: Robe Gable | C7: 2100 | D7: 18 | E7: 600 | F7: Light Grey U708 Robe Gable | G7: Robe | H7: 1
A8: 6 | B8: Hanging Rail | C8: 760 | D8: 25 | E8: 25 | F8: Wardrobe Hanging Rail | G8: Robe Accessories | H8: 1
A9: 7 | B9: T-Bar Handle | C9: 160 | D9: 20 | E9: 30 | F9: T-Bar Robe Handle | G9: Robe Accessories | H9: 2

Sheet T1V Robe Manifest
A1: Item Number | B1: Description | C1: Width | D1: Height | E1: Depth | F1: Item Description | G1: Room | H1: Qty
A2: 0 | B2: Robe Side Panel | C2: 2100 | D2: 18 | E2: 600 | F2: Light Grey U708 Robe Side Panel | G2: Robe | H2: 2
A3: 1 | B3: Robe Top Panel | C3: 800 | D3: 18 | E3: 600 | F3: Light Grey U708 Robe Top Panel | G3: Robe | H3: 1
A4: 2 | B4: Robe Base Panel | C4: 800 | D4: 18 | E4: 600 | F4: Light Grey U708 Robe Base Panel | G4: Robe | H4: 1
A5: 3 | B5: Robe Shelf | C5: 760 | D5: 18 | E5: 550 | F5: Light Grey U708 Robe Shelf | G5: Robe | H5: 3
A6: 4 | B6: Robe Door | C6: 2100 | D6: 400 | E6: 18 | F6: Light Grey U708 Robe Door | G6: Robe | H6: 2
A7: 5 | B7: Robe Gable | C7: 2100 | D7: 18 | E7: 600 | F7: Light Grey U708 Robe Gable | G7: Robe | H7: 1
A8: 6 | B8: Hanging Rail | C8: 760 | D8: 25 | E8: 25 | F8: Wardrobe Hanging Rail | G8: Robe Accessories | H8: 1
A9: 7 | B9: T-Bar Handle | C9: 160 | D9: 20 | E9: 30 | F9: T-Bar Robe Handle | G9: Robe Accessories | H9: 2

Sheet T2 Robe Manifest
A1: Item Number | B1: Description | C1: Width | D1: Height | E1: Depth | F1: Item Description | G1: Room | H1: Qty
A2: 0 | B2: Robe Side Panel | C2: 2100 | D2: 18 | E2: 600 | F2: Light Grey U708 Robe Side Panel | G2: Robe | H2: 2
A3: 1 | B3: Robe Top Panel | C3: 1000 | D3: 18 | E3: 600 | F3: Light Grey U708 Robe Top Panel | G3: Robe | H3: 1
A4: 2 | B4: Robe Base Panel | C4: 1000 | D4: 18 | E4: 600 | F4: Light Grey U708 Robe Base Panel | G4: Robe | H4: 1
A5: 3 | B5: Robe Shelf | C5: 960 | D5: 18 | E5: 550 | F5: Light Grey U708 Robe Shelf | G5: Robe | H5: 4
A6: 4 | B6: Robe Door | C6: 2100 | D6: 500 | E6: 18 | F6: Light Grey U708 Robe Door | G6: Robe | H6: 2
A7: 5 | B7: Robe Gable | C7: 2100 | D7: 18 | E7: 600 | F7: Light Grey U708 Robe Gable | G7: Robe | H7: 1
A8: 6 | B8: Hanging Rail | C8: 960 | D8: 25 | E8: 25 | F8: Wardrobe Hanging Rail | G8: Robe Accessories | H8: 1
A9: 7 | B9: T-Bar Handle | C9: 160 | D9: 20 | E9: 30 | F9: T-Bar Robe Handle | G9: Robe Accessories | H9: 2

Sheet T3 Robe Manifest
A1: Item Number | B1: Description | C1: Width | D1: Height | E1: Depth | F1: Item Description | G1: Room | H1: Qty
A2: 0 | B2: Robe Side Panel | C2: 2100 | D2: 18 | E2: 600 | F2: Light Grey U708 Robe Side Panel | G2: Robe | H2: 2
A3: 1 | B3: Robe Top Panel | C3: 1200 | D3: 18 | E3: 600 | F3: Light Grey U708 Robe Top Panel | G3: Robe | H3: 1
A4: 2 | B4: Robe Base Panel | C4: 1200 | D4: 18 | E4: 600 | F4: Light Grey U708 Robe Base Panel | G4: Robe | H4: 1
A5: 3 | B5: Robe Shelf | C5: 1160 | D5: 18 | E5: 550 | F5: Light Grey U708 Robe Shelf | G5: Robe | H5: 5
A6: 4 | B6: Robe Door | C6: 2100 | D6: 400 | E6: 18 | F6: Light Grey U708 Robe Door | G6: Robe | H6: 3
A7: 5 | B7: Robe Gable | C7: 2100 | D7: 18 | E7: 600 | F7: Light Grey U708 Robe Gable | G7: Robe | H7: 1
A8: 6 | B8: Hanging Rail | C8: 1160 | D8: 25 | E8: 25 | F8: Wardrobe Hanging Rail | G8: Robe Accessories | H8: 1
A9: 7 | B9: T-Bar Handle | C9: 160 | D9: 20 | E9: 30 | F9: T-Bar Robe Handle | G9: Robe Accessories | H9: 3

Sheet Type Mapping
A1: Type | B1: Spec Sheet Column | C1: Kitchen Manifest Sheet | D1: Robe Manifest Sheet | E1: Unit Count | F1: Default Kitchen Qty | G1: Default Robe Qty | H1: Default Utility Qty | I1: Default Vanity Qty | J1: Default Pantry Qty | K1: Notes
A2: T1 | B2: Spec Sheet!B:B | C2: T1 Manifest | D2: T1 Robe Manifest | E2: {=COUNTIF('Quantity Sheet'!$E$2:$E$41,A2)} -> 9 | F2: 1 | G2: 1 | H2: 1 | I2: 0 | J2: 0 | K2: 1-bed layout with utility. Synthetic demo manifest.
A3: T1V | B3: Spec Sheet!C:C | C3: T1V Manifest | D3: T1V Robe Manifest | E3: {=COUNTIF('Quantity Sheet'!$E$2:$E$41,A3)} -> 7 | F3: 1 | G3: 1 | H3: 0 | I3: 0 | J3: 0 | K3: 1-bed variant with Levanto kitchen worktop and no utility.
A4: T2 | B4: Spec Sheet!D:D | C4: T2 Manifest | D4: T2 Robe Manifest | E4: {=COUNTIF('Quantity Sheet'!$E$2:$E$41,A4)} -> 14 | F4: 1 | G4: 2 | H4: 1 | I4: 0 | J4: 0 | K4: 2-bed layout with Indesit appliance package.
A5: T3 | B5: Spec Sheet!E:E | C5: T3 Manifest | D5: T3 Robe Manifest | E5: {=COUNTIF('Quantity Sheet'!$E$2:$E$41,A5)} -> 10 | F5: 1 | G5: 3 | H5: 1 | I5: 1 | J5: 1 | K5: 3-bed layout with island and Bosch appliance package.

Sheet Demo Delivery Schedule
A1: Developer | B1: Project / Site | C1: House No. | D1: Kitchen Unit ID | E1: Type | F1: Planned Delivery Date | G1: Delivery Batch | H1: Kitchen | I1: Robe | J1: Utility | K1: Vanity Unit | L1: Pantry
A2: MOCKDEV | B2: The Avenue MOCKSITE | C2: 1 | D2: AVENUE-H001-KITCHEN | E2: T3 | F2: 46209 | G2: BATCH-01 | H2: 1 | I2: 3 | J2: 1 | K2: 1 | L2: 1
A3: MOCKDEV | B3: The Avenue MOCKSITE | C3: 2 | D3: AVENUE-H002-KITCHEN | E3: T3 | F3: 46209 | G3: BATCH-01 | H3: 1 | I3: 3 | J3: 1 | K3: 1 | L3: 1
A4: MOCKDEV | B4: The Avenue MOCKSITE | C4: 3 | D4: AVENUE-H003-KITCHEN | E4: T3 | F4: 46209 | G4: BATCH-01 | H4: 1 | I4: 3 | J4: 1 | K4: 1 | L4: 1
A5: MOCKDEV | B5: The Avenue MOCKSITE | C5: 4 | D5: AVENUE-H004-KITCHEN | E5: T3 | F5: 46209 | G5: BATCH-01 | H5: 1 | I5: 3 | J5: 1 | K5: 1 | L5: 1
A6: MOCKDEV | B6: The Avenue MOCKSITE | C6: 5 | D6: AVENUE-H005-KITCHEN | E6: T3 | F6: 46216 | G6: BATCH-02 | H6: 1 | I6: 3 | J6: 1 | K6: 1 | L6: 1
A7: MOCKDEV | B7: The Avenue MOCKSITE | C7: 6 | D7: AVENUE-H006-KITCHEN | E7: T3 | F7: 46216 | G7: BATCH-02 | H7: 1 | I7: 3 | J7: 1 | K7: 1 | L7: 1
A8: MOCKDEV | B8: The Avenue MOCKSITE | C8: 7 | D8: AVENUE-H007-KITCHEN | E8: T2 | F8: 46216 | G8: BATCH-02 | H8: 1 | I8: 2 | J8: 1 | K8: 0 | L8: 0
A9: MOCKDEV | B9: The Avenue MOCKSITE | C9: 8 | D9: AVENUE-H008-KITCHEN | E9: T2 | F9: 46216 | G9: BATCH-02 | H9: 1 | I9: 2 | J9: 1 | K9: 0 | L9: 0
A10: MOCKDEV | B10: The Avenue MOCKSITE | C10: 9 | D10: AVENUE-H009-KITCHEN | E10: T2 | F10: 46223 | G10: BATCH-03 | H10: 1 | I10: 2 | J10: 1 | K10: 0 | L10: 0
A11: MOCKDEV | B11: The Avenue MOCKSITE | C11: 10 | D11: AVENUE-H010-KITCHEN | E11: T2 | F11: 46223 | G11: BATCH-03 | H11: 1 | I11: 2 | J11: 1 | K11: 0 | L11: 0
A12: MOCKDEV | B12: The Avenue MOCKSITE | C12: 11 | D12: AVENUE-H011-KITCHEN | E12: T2 | F12: 46223 | G12: BATCH-03 | H12: 1 | I12: 2 | J12: 1 | K12: 0 | L12: 0
A13: MOCKDEV | B13: The Avenue MOCKSITE | C13: 12 | D13: AVENUE-H012-KITCHEN | E13: T2 | F13: 46223 | G13: BATCH-03 | H13: 1 | I13: 2 | J13: 1 | K13: 0 | L13: 0
... A41: MOCKDEV | B41: The Lane MOCKSITE | C41: 16 | D41: LANE-H016-KITCHEN | E41: T1V | F41: 46272 | G41: BATCH-10 | H41: 1 | I41: 1 | J41: 0 | K41: 0 | L41: 0

Sheet Task Schedule Template
A1: Sequence | B1: Stage | C1: Start Offset vs Delivery (days) | D1: End Offset vs Delivery (days) | E1: Department | F1: Completion Method | G1: Notes
A2: 1 | B2: Spec Agreed | C2: -75 | D2: -70 | E2: Technical / Commercial | F2: Manual approval | G2: Project-level or unit-level specification approved.
A3: 2 | B3: Survey | C3: -60 | D3: -55 | E3: Site Survey | F3: Confirm survey | G3: Site manager confirms room survey.
A4: 3 | B4: Drawing | C4: -50 | D4: -40 | E4: Drawing Office | F4: Upload drawings | G4: Drawing file upload completes stage.
A5: 4 | B5: Export | C5: -35 | D5: -34 | E5: Export / CNC Prep | F5: Print and scan unit QR identifier | G5: Identifier QR code is generated and scanned.
A6: 5 | B6: Manufacture | C6: -28 | D6: -14 | E6: Manufacturing | F6: Print and scan manifest QR | G6: Manufacturing completion is confirmed from manifest QR.
A7: 6 | B7: Assembly | C7: -13 | D7: -10 | E7: Assembly | F7: Scan all cabinet-line and grouped labels | G7: All required assembly labels must be scanned.
A8: 7 | B8: Despatch | C8: -5 | D8: -3 | E8: Despatch | F8: Scan all labels and upload photos | G8: All required labels scanned before load leaves factory.
A9: 8 | B9: Delivery | C9: 0 | D9: 0 | E9: Delivery | F9: Scan all labels and upload photos | G9: Delivery day is the scheduling anchor (day 0).
A10: 9 | B10: Fitting | C10: 1 | D10: 5 | E10: Fitting | F10: Upload minimum fitting photos | G10: Identifier QR used by fitter; minimum photo quota required.
A11: 10 | B11: Handover | C11: 6 | D11: 10 | E11: Contracts / Handover | F11: Upload handover sheet | G11: Final handover evidence uploaded.

Sheet Manifest Summary
A1: Manifest Sheet | B1: Manifest Category | C1: Line Count | D1: Total Qty | E1: Notes
A2: T1 Manifest | B2: Kitchen + Utility | C2: {=COUNTA('T1 Manifest'!B2:B200)} -> 19 | D2: {=SUM('T1 Manifest'!H2:H200)} -> 31 | E2: Synthetic demo
A3: T1V Manifest | B3: Kitchen | C3: {=COUNTA('T1V Manifest'!B2:B200)} -> 15 | D3: {=SUM('T1V Manifest'!H2:H200)} -> 25 | E3: Synthetic demo
A4: T2 Manifest | B4: Kitchen + Utility | C4: {=COUNTA('T2 Manifest'!B2:B200)} -> 30 | D4: {=SUM('T2 Manifest'!H2:H200)} -> 48 | E4: Synthetic demo
A5: T3 Manifest | B5: Kitchen + Utility | C5: {=COUNTA('T3 Manifest'!B2:B200)} -> 42 | D5: {=SUM('T3 Manifest'!H2:H200)} -> 79 | E5: Source screenshot expanded with synthetic appliance rows
A6: T1 Robe Manifest | B6: Robe | C6: {=COUNTA('T1 Robe Manifest'!B2:B200)} -> 8 | D6: {=SUM('T1 Robe Manifest'!H2:H200)} -> 13 | E6: Per wardrobe
A7: T1V Robe Manifest | B7: Robe | C7: {=COUNTA('T1V Robe Manifest'!B2:B200)} -> 8 | D7: {=SUM('T1V Robe Manifest'!H2:H200)} -> 13 | E7: Per wardrobe
A8: T2 Robe Manifest | B8: Robe | C8: {=COUNTA('T2 Robe Manifest'!B2:B200)} -> 8 | D8: {=SUM('T2 Robe Manifest'!H2:H200)} -> 14 | E8: Per wardrobe
A9: T3 Robe Manifest | B9: Robe | C9: {=COUNTA('T3 Robe Manifest'!B2:B200)} -> 8 | D9: {=SUM('T3 Robe Manifest'!H2:H200)} -> 17 | E9: Per wardrobe

Sheet Demo Summary
A1: Fitzgerald Kitchens Synthetic Demo Dataset Summary
A3: Metric | B3: Value | D3: Type | E3: Units | F3: Kitchens | G3: Robes | H3: Utilities
A4: Projects / Sites | B4: {=COUNTA(_xlfn.UNIQUE('Quantity Sheet'!B2:B41))} -> 2 | D4: T1 | E4: {=COUNTIF('Quantity Sheet'!$E$2:$E$41,D4)} -> 9 | F4: {=SUMIF('Quantity Sheet'!$E$2:$E$41,D4,'Quantity Sheet'!$F$2:$F$41)} -> 9 | G4: {=SUMIF('Quantity Sheet'!$E$2:$E$41,D4,'Quantity Sheet'!$G$2:$G$41)} -> 9 | H4: {=SUMIF('Quantity Sheet'!$E$2:$E$41,D4,'Quantity Sheet'!$H$2:$H$41)} -> 9
A5: Kitchen Units | B5: {=SUM('Quantity Sheet'!F2:F41)} -> 40 | D5: T1V | E5: {=COUNTIF('Quantity Sheet'!$E$2:$E$41,D5)} -> 7 | F5: {=SUMIF('Quantity Sheet'!$E$2:$E$41,D5,'Quantity Sheet'!$F$2:$F$41)} -> 7 | G5: {=SUMIF('Quantity Sheet'!$E$2:$E$41,D5,'Quantity Sheet'!$G$2:$G$41)} -> 7 | H5: {=SUMIF('Quantity Sheet'!$E$2:$E$41,D5,'Quantity Sheet'!$H$2:$H$41)} -> 0
A6: Wardrobe Subunits | B6: {=SUM('Quantity Sheet'!G2:G41)} -> 74 | D6: T2 | E6: {=COUNTIF('Quantity Sheet'!$E$2:$E$41,D6)} -> 14 | F6: {=SUMIF('Quantity Sheet'!$E$2:$E$41,D6,'Quantity Sheet'!$F$2:$F$41)} -> 14 | G6: {=SUMIF('Quantity Sheet'!$E$2:$E$41,D6,'Quantity Sheet'!$G$2:$G$41)} -> 28 | H6: {=SUMIF('Quantity Sheet'!$E$2:$E$41,D6,'Quantity Sheet'!$H$2:$H$41)} -> 14
A7: Utility Subunits | B7: {=SUM('Quantity Sheet'!H2:H41)} -> 33 | D7: T3 | E7: {=COUNTIF('Quantity Sheet'!$E$2:$E$41,D7)} -> 10 | F7: {=SUMIF('Quantity Sheet'!$E$2:$E$41,D7,'Quantity Sheet'!$F$2:$F$41)} -> 10 | G7: {=SUMIF('Quantity Sheet'!$E$2:$E$41,D7,'Quantity Sheet'!$G$2:$G$41)} -> 30 | H7: {=SUMIF('Quantity Sheet'!$E$2:$E$41,D7,'Quantity Sheet'!$H$2:$H$41)} -> 10
A8: Vanity Subunits | B8: {=SUM('Quantity Sheet'!I2:I41)} -> 10 | D8: Total | E8: {=SUM(E4:E7)} -> 40 | F8: {=SUM(F4:F7)} -> 40 | G8: {=SUM(G4:G7)} -> 74 | H8: {=SUM(H4:H7)} -> 33
A9: Pantry Subunits | B9: {=SUM('Quantity Sheet'!J2:J41)} -> 10
A10: Kitchen Manifest Templates | B10: 4
A11: Wardrobe Manifest Templates | B11: 4
A13: This summary is formula-driven. The dataset is suitable for testing the import parser, unit/subunit creation, project-level spec mapping, unit-level manifest snapshots, label generation and delivery-date-based task generation.
